<?xml version="1.0"?>
<!-- URDF of the kitchen scene. -->
<robot name="kitchen_scene">

    <!-- objects in the scene -->

    <link name="base_link">
        <inertial>
            <origin xyz="0 0 0" rpy="0 0 0"/>
            <mass value="0"/>
            <inertia ixx="1" ixy="0" ixz="0" iyy="1" iyz="0" izz="1"/>
        </inertial>
    </link>


    <link name="table" concave="yes">
        <inertial>
            <origin xyz="0 0 0" rpy="0 0 0"/>
            <mass value="1"/>
            <inertia ixx="1" ixy="0" ixz="0" iyy="1" iyz="0" izz="1"/>
        </inertial>
        <visual>
            <geometry>
                <mesh filename="./meshes/table.stl"/>
            </geometry>
        </visual>
        <collision concave="yes">
            <geometry>
                <mesh filename="./meshes/table.stl"/>
            </geometry>
        </collision>
    </link>

    <link name="file_cabinet_body" concave="yes">
        <inertial>
            <origin xyz="0 0 0" rpy="0 0 0"/>
            <mass value="1"/>
            <inertia ixx="1" ixy="0" ixz="0" iyy="1" iyz="0" izz="1"/>
        </inertial>

        <visual>
            <geometry>
                <mesh filename="./meshes/file_cabinet_body.stl"/>
            </geometry>
        </visual>
        <collision concave="yes">
            <geometry>
                <mesh filename="./meshes/file_cabinet_body.stl"/>
            </geometry>
        </collision>
    </link>

    <link name="file_cabinet_drawer_bottom" concave="yes">
        <inertial>
            <origin xyz="0 0 0" rpy="0 0 0"/>
            <mass value="1"/>
            <inertia ixx="1" ixy="0" ixz="0" iyy="1" iyz="0" izz="1"/>
        </inertial>

        <visual>
            <geometry>
                <mesh filename="./meshes/file_cabinet_drawer_bottom.stl"/>
            </geometry>
        </visual>
        <collision concave="yes">
            <geometry>
                <mesh filename="./meshes/file_cabinet_drawer_bottom.stl"/>
            </geometry>
        </collision>
    </link>

    <link name="file_cabinet_drawer_top" concave="yes">
        <inertial>
            <origin xyz="0 0 0" rpy="0 0 0"/>
            <mass value="1"/>
            <inertia ixx="1" ixy="0" ixz="0" iyy="1" iyz="0" izz="1"/>
        </inertial>

        <visual>
            <geometry>
                <mesh filename="./meshes/file_cabinet_drawer_top.stl"/>
            </geometry>
        </visual>
        <collision concave="yes">
            <geometry>
                <mesh filename="./meshes/file_cabinet_drawer_top.stl"/>
            </geometry>
        </collision>
    </link>

   <!-- joints in the scene. -->

    <!-- some joints are defined by the nature of the environment: for example,
    the table is fixed in the world, and the filing cabinet drawers can move in
    and out. -->
    <joint name="table_joint" type="fixed">
        <parent link="base_link"/>
        <child link="table"/>
        <origin xyz="0.0 0.0 0.69" rpy="0.0 0.0 0.0"/>
    </joint>

    <joint name="file_cabinet_body_joint" type="fixed">
        <parent link="base_link"/>
        <child link="file_cabinet_body"/>
        <origin xyz="0.0 0.0 0.69" rpy="0.0 0.0 0.0"/>
    </joint>

    <joint name="file_cabinet_drawer_bottom_joint" type="prismatic">
        <parent link="file_cabinet_body"/>
        <child link="file_cabinet_drawer_bottom"/>
        <origin xyz="0.0 0.0 0.0" rpy="0.0 0.0 0.0"/>
        <axis xyz="0.0 -1.0 0.0"/>
        <limit effort="1000.0" lower="0.0" upper="0.24" velocity="0.5"/>
    </joint>

    <joint name="file_cabinet_drawer_top_joint" type="prismatic">
        <parent link="file_cabinet_body"/>
        <child link="file_cabinet_drawer_top"/>
        <origin xyz="0.0 0.0 0.0" rpy="0.0 0.0 0.0"/>
        <axis xyz="0.0 -1.0 0.0"/>
        <limit effort="1000.0" lower="0.0" upper="0.24" velocity="0.5"/>
    </joint>

</robot>
